Workbook
Name 그룹세부구분: [1]기본!#REF!
Name 그룹연구비: [1]기본!$G$4:$G$33
Name 그룹전체: [1]기본!$A$4:$O$260
Name 그룹총괄구분: [1]기본!#REF!

Sheet 드롭다운목록
B2: 제작소 특화 프로그램 | D2: 자기발견 | F2: 자립지원 | H2: 일반운영비 | K2: 세목 - 세세목 | M2: 업무추진비
B3: 공동운영프로그램 | D3: 진로설계 | F3: 교육훈련-학원, 인터넷강의, 멘토링 | H3: 일반수용비(홍보비 외) | K3: 제작소특화프로그램 - 공동운영프로그램 | M3: 회의비
B4: 소그룹 커뮤니티 | D4: 마음건강 | F4: 교육훈련-불가피한 교재(재료) | H4: 일반수용비(홍보비) | K4: 제작소특화프로그램 - 멘토링 | M4: 사업추진비
B5: 멘토링 | D5: 기타 | F5: 교육훈련-자격증 응시료 | H5: 공공요금 및 제세 | K5: 제작소특화프로그램 - 강의(특강) 등
B6: 강의 | F6: 교육훈련-자격응시 불가피한 재료 | H6: 특근매식비 | K6: 제작소특화프로그램 - 소그룹 커뮤니티
B7: 프로그램 운영 부대비용 | F7: 교육훈련-면접 사진, 정장대여 | K7: 자기발견 - 진로설계
B8: 기타 | F8: 교육훈련-(창업)시제품 개발 재료 | K8: 자기발견 - 마음건강
F9: 교육훈련-교육/면접 등 참가비 | K9: 자립지원 - 교육훈련
F10: 인턴쉽 | K10: 자립지원 - 인턴쉽
F11: 기타 | K11: 기타 - 애로사항
K12: 기타 - 기타

Sheet 사업비 사용실적 명세서
C2: 사업비 사용실적 명세서
C3: 1. 기관명 : | D3: ㅇㅇ제작소
C4: 가. 사업비 집행현황 총괄(연차별 집행현황)
C6: 비목 구분 | E6: 예산 (A) | I6: 집행금액 (B) | J6: 불인정 차감 전 잔액 (A-B) | K6: 불인정 금액 (C) | L6: 불인정 차감 후 잔액 (A-B-C) | M6: 집행률 | N6: 비고 | Q6: - 선택 -
E7: 협약예산 | F7: 변경예산 | G7: 집행예산 | H7: 재단승인 여부 | Q7: 구두 승인(추후 확인)
C8: 직접비 | D8: 역량강화지원금 | E8: 1000000 | F8: 900000 | G8: =IF(F8="",E8,F8) -> 900000 | I8: =+'직접비-역량강화지원금'!J7 -> 1550000 | J8: =G8-I8 -> -650000 | K8: =+I82 -> 0 | L8: =J8-K8 -> -650000 | M8: =IF(G8=0,0,I8/G8) -> 1.7222222 | Q8: 공문 승인
G9: =IF(F9="",E9,F9) -> 0 | J9: =G9-I9 -> 0 | K9: =+I83 -> 0 | L9: =J9-K9 -> 0 | M9: =IF(G9=0,0,I9/G9) -> 0 | Q9: 미승인
G10: =IF(F10="",E10,F10) -> 0 | J10: =G10-I10 -> 0 | K10: =+I84 -> 0 | L10: =J10-K10 -> 0 | M10: =IF(G10=0,0,I10/G10) -> 0
G11: =IF(F11="",E11,F11) -> 0 | J11: =G11-I11 -> 0 | K11: =+I85 -> 0 | L11: =J11-K11 -> 0 | M11: =IF(G11=0,0,I11/G11) -> 0
J12: =G12-I12 -> 0 | K12: =+I86 -> 0 | L12: =J12-K12 -> 0 | M12: =IF(G12=0,0,I12/G12) -> 0
G13: =IF(F13="",E13,F13) -> 0 | J13: =G13-I13 -> 0 | K13: =+I87 -> 0 | L13: =J13-K13 -> 0 | M13: =IF(G13=0,0,I13/G13) -> 0
D14: 합 계 | E14: =SUM(E8:E13) -> 1000000 | F14: =SUM(F8:F13) -> 900000 | G14: =SUM(G8:G13) -> 900000 | I14: =SUM(I8:I13) -> 1550000 | J14: =G14-I14 -> -650000 | K14: =SUM(K8:K13) -> 0 | L14: =J14-K14 -> -650000 | M14: =IF(G14=0,0,I14/G14) -> 1.7222222 | R14: 잔액 검증 | S14: 통장잔액 | T14: 통장-실제
C15: 간접비 | D15: 보수 | E15: =+E33 -> 50000000 | F15: =+F33 -> 45000000 | G15: =IF(F15="",E15,F15) -> 45000000 | I15: =+I33 -> 43050000 | J15: =G15-I15 -> 1950000 | K15: =+I88 -> 0 | L15: =J15-K15 -> 1950000 | M15: =IF(G15=0,0,I15/G15) -> 0.95666667 | R15: 직접비 | T15: =IF(S15-L14=0,"TRUE",S15-L14) -> 650000
D16: 일반운영비 | E16: =+E34+E35+E36+E37 -> 5600000 | F16: =+F34+F35+F36+F37 -> 3000000 | G16: =IF(F16="",E16,F16) -> 3000000 | I16: =+I34+I35+I36+I37 -> 401456 | J16: =G16-I16 -> 2598544 | K16: =+I89 -> 0 | L16: =J16-K16 -> 2598544 | M16: =IF(G16=0,0,I16/G16) -> 0.13381867 | R16: 간접비 | T16: =IF(S16-L24=0,"TRUE",S16-L24) -> -8957434
D17: 여비 | E17: =+E38 -> 500000 | F17: =+F38 -> 400000 | G17: =IF(F17="",E17,F17) -> 400000 | I17: =+I38 -> 61110 | J17: =G17-I17 -> 338890 | K17: =+I90 -> 0 | L17: =J17-K17 -> 338890 | M17: =IF(G17=0,0,I17/G17) -> 0.152775
D18: 업무추진비 | E18: =+E39 -> 300000 | F18: =+F39 -> 300000 | G18: =IF(F18="",E18,F18) -> 300000 | I18: =+I39 -> 280000 | J18: =G18-I18 -> 20000 | K18: =+I91 -> 0 | L18: =J18-K18 -> 20000 | M18: =IF(G18=0,0,I18/G18) -> 0.93333333
E19: =+E40 -> 100000 | F19: =+F40 -> 100000 | G19: =IF(F19="",E19,F19) -> 100000 | I19: =+I40 -> 0 | J19: =G19-I19 -> 100000 | K19: =+I92 -> 0 | L19: =J19-K19 -> 100000 | M19: =IF(G19=0,0,I19/G19) -> 0
D20: 기타직보수 | E20: =+E41 -> 5000000 | F20: =+F41 -> 4500000 | G20: =IF(F20="",E20,F20) -> 4500000 | I20: =+I41 -> 550000 | J20: =G20-I20 -> 3950000 | K20: =+I93 -> 0 | L20: =J20-K20 -> 3950000 | M20: =IF(G20=0,0,I20/G20) -> 0.12222222
D21: 기타사항 | G21: =IF(F21="",E21,F21) -> 0 | J21: =G21-I21 -> 0 | K21: =+I94 -> 0 | L21: =J21-K21 -> 0 | M21: =IF(G21=0,0,I21/G21) -> 0
D22: 이자 및 제세금 | G22: =IF(F22="",E22,F22) -> 0 | J22: =G22-I22 -> 0 | K22: =+I95 -> 0 | L22: =J22-K22 -> 0 | M22: =IF(G22=0,0,I22/G22) -> 0
D23: 보증금 | G23: =IF(F23="",E23,F23) -> 0 | J23: =G23-I23 -> 0 | K23: =+I96 -> 0 | L23: =J23-K23 -> 0 | M23: =IF(G23=0,0,I23/G23) -> 0
D24: 합 계 | E24: =SUM(E15:E23) -> 61500000 | F24: =SUM(F15:F23) -> 53300000 | G24: =SUM(G15:G23) -> 53300000 | I24: =SUM(I15:I23) -> 44342566 | J24: =G24-I24 -> 8957434 | K24: =SUM(K15:K23) -> 0 | L24: =J24-K24 -> 8957434 | M24: =IF(G24=0,0,I24/G24) -> 0.83194308
C25: 합 계 | E25: =E14+E24 -> 62500000 | F25: =F14+F24 -> 54200000 | G25: =G14+G24 -> 54200000 | H25: =H14+H24 -> 0 | I25: =I14+I24 -> 45892566 | J25: =J14+J24 -> 8307434 | K25: =K14+K24 -> 0 | L25: =L14+L24 -> 8307434 | M25: =IF(G25=0,0,I25/G25) -> 0.84672631
C26: ※ 1. 협약예산과 집행예산의 차이가 없는경우 변경예산에는 공란으로 표시
C27: 2. 당초계획대비 사용금액이 변경된 사항에 대해서는 비고란에 구체적 표기
C29: 나. 간접비 세목별 집행현황 총괄
C31: 비목 구분 | E31: 예산 (A) | I31: 집행금액 (B) | J31: 불인정 차감 전 잔액 (A-B) | K31: 불인정 금액 (C) | L31: 불인정 차감 후 잔액 (A-B-C) | M31: 집행률 | N31: 비고
E32: 협약예산 | F32: 변경예산 | G32: 집행예산 | H32: 재단승인 여부
C33: 보수 | D33: 인건비 | E33: 50000000 | F33: 45000000 | G33: =IF(F33="",E33,F33) -> 45000000 | I33: =+'간접비-보수'!I13 -> 43050000 | J33: =G33-I33 -> 1950000 | K33: =K15 -> 0 | L33: =J33-K33 -> 1950000 | M33: =IF(G33=0,0,I33/G33) -> 0.95666667
C34: 일반운영비 | D34: 일반수용비(홍보비 외) | E34: 1000000 | F34: 900000 | G34: =IF(F34="",E34,F34) -> 900000 | I34: =+'간접비-일반운영비'!J3 -> 351456 | J34: =G34-I34 -> 548544 | K34: =K16 -> 0 | L34: =J34-K34 -> 548544 | M34: =IF(G34=0,0,I34/G34) -> 0.39050667
D35: 일반수용비(홍보비) | E35: 1100000 | F35: 800000 | G35: =IF(F35="",E35,F35) -> 800000 | I35: =+'간접비-일반운영비'!J4 -> 50000 | J35: =G35-I35 -> 750000 | K35: =K16 -> 0 | L35: =J35-K35 -> 750000 | M35: =IF(G35=0,0,I35/G35) -> 0.0625
D36: 공공요금 및 제세 | E36: 1500000 | F36: 700000 | G36: =IF(F36="",E36,F36) -> 700000 | I36: =+'간접비-일반운영비'!J5 -> 0 | J36: =G36-I36 -> 700000 | K36: =K16 -> 0 | L36: =J36-K36 -> 700000 | M36: =IF(G36=0,0,I36/G36) -> 0
D37: 특근매식비 | E37: 2000000 | F37: 600000 | G37: =IF(F37="",E37,F37) -> 600000 | I37: =+'간접비-일반운영비'!J6 -> 0 | J37: =G37-I37 -> 600000 | K37: =K17 -> 0 | L37: =J37-K37 -> 600000 | M37: =IF(G37=0,0,I37/G37) -> 0
C38: 여비 | D38: 국내여비 | E38: 500000 | F38: 400000 | G38: =IF(F38="",E38,F38) -> 400000 | I38: =+'간접비-여비'!H7 -> 61110 | J38: =G38-I38 -> 338890 | K38: =K17 -> 0 | L38: =J38-K38 -> 338890 | M38: =IF(G38=0,0,I38/G38) -> 0.152775
C39: 업무추진비 | D39: 사업추진비 | E39: 300000 | F39: 300000 | G39: =IF(F39="",E39,F39) -> 300000 | I39: =+'간접비-업무추진비'!I9 -> 280000 | J39: =G39-I39 -> 20000 | K39: =K18 -> 0 | L39: =J39-K39 -> 20000 | M39: =IF(G39=0,0,I39/G39) -> 0.93333333
D40: 회의비 | E40: 100000 | F40: 100000 | G40: =IF(F40="",E40,F40) -> 100000 | J40: =G40-I40 -> 100000 | K40: =K19 -> 0 | L40: =J40-K40 -> 100000 | M40: =IF(G40=0,0,I40/G40) -> 0
C41: 기타직보수 | D41: 기타직보수 | E41: 5000000 | F41: 4500000 | G41: =IF(F41="",E41,F41) -> 4500000 | I41: =+'간접비-기타직보수'!I7 -> 550000 | J41: =G41-I41 -> 3950000 | K41: =K20 -> 0 | L41: =J41-K41 -> 3950000 | M41: =IF(G41=0,0,I41/G41) -> 0.12222222
C42: 기타사항 | D42: 기타 | G42: =IF(F42="",E42,F42) -> 0 | J42: =G42-I42 -> 0 | K42: =K23 -> 0 | L42: =J42-K42 -> 0 | M42: =IF(G42=0,0,I42/G42) -> 0
C43: 이자 및 제세금 | D43: 이자 및 제세금(간) | G43: =IF(F43="",E43,F43) -> 0 | J43: =G43-I43 -> 0 | K43: =K22 -> 0 | L43: =J43-K43 -> 0 | M43: =IF(G43=0,0,I43/G43) -> 0
C44: 보증금 | D44: 보증금 | G44: =IF(F44="",E44,F44) -> 0 | J44: =G44-I44 -> 0 | K44: =K21 -> 0 | L44: =J44-K44 -> 0 | M44: =IF(G44=0,0,I44/G44) -> 0
...

Sheet 직접비-역량강화지원금
C2: 직접비 - 역량강화지원금 | J2: 집행예산액 | K2: =+'사업비 사용실적 명세서'!G8 -> 900000 | M2: (참고) 세목체계 정리
J3: 집행금액 | K3: =+'사업비 사용실적 명세서'!I8 -> 1550000 | L3: =+J7-K3 -> 0 | M3: 세목 | N3: 세세목
J4: 미집행(초과집행) | K4: =+K2-K3 -> -650000 | M4: 제작소특화프로그램 | N4: 공동운영프로그램/멘토링/강의(특강) 등
M5: 자기발견 | N5: 진로설계/마음건강
C6: 증빙 번호 | D6: 집행일 | E6: 세목 - 세세목 | F6: 거래처명 | G6: 참여청년 | H6: 적요 | I6: 집행방법 (카드, 계좌이체 등) | J6: 지출금액 (합계) | K6: 비고 | M6: 자립지원 | N6: 교육훈력/인턴쉽
J7: =SUM(J8:J50000) -> 1550000 | M7: 기타 | N7: 애로사항/기타
B8: =CONCATENATE(E8,G8) -> 제작소특화프로그램 - 멘토링홍길동 | C8: 1 | D8: 45383 | E8: 제작소특화프로그램 - 멘토링 | F8: 호시담 | G8: 홍길동 | H8: 참여청년 심리상담 비용 2건 지급(윤원일) | I8: 계좌이체 | J8: 100000 | M8: 운영지침 - 비목별세부집행기준 참고(p5)
B9: =CONCATENATE(E9,G9) -> 자기발견 - 마음건강홍길순 | C9: 2 | D9: 45413 | E9: 자기발견 - 마음건강 | F9: 상공회의소 | G9: 홍길순 | H9: 자격증 응시료 자기부담금(우미리) | I9: 계좌이체 | J9: 50000 | M9: *반드시 세목 종류 선택하여 작성
B10: =CONCATENATE(E10,G10) -> 제작소특화프로그램 - 소그룹 커뮤니티홍길순 | C10: 3 | E10: 제작소특화프로그램 - 소그룹 커뮤니티 | G10: 홍길순 | J10: 500000
B11: =CONCATENATE(E11,G11) -> 홍길순 | C11: 4 | G11: 홍길순 | J11: 900000
B12: =CONCATENATE(E12,G12) | C12: 5
B13: =CONCATENATE(E13,G13) | C13: 6
B14: =CONCATENATE(E14,G14) | C14: 7
B15: =CONCATENATE(E15,G15) | C15: 8
B16: =CONCATENATE(E16,G16) | C16: 9
B17: =CONCATENATE(E17,G17) | C17: 10
B18: =CONCATENATE(E18,G18) | C18: 11
B19: =CONCATENATE(E19,G19) | C19: 12
B20: =CONCATENATE(E20,G20) | C20: 13
B21: =CONCATENATE(E21,G21) | C21: 14
B22: =CONCATENATE(E22,G22) | C22: 15
B23: =CONCATENATE(E23,G23) | C23: 16
... B320: =CONCATENATE(E320,G320) | C320: 313

Sheet 참여청년현황
B1: [참여청년 한도내 집행 여부 검토]
B2: 연번 | C2: 성명 | D2: 주민번호 앞 6자리 | E2: 총 예산 및 집행 | K2: 애로사항 해소지원 만
E3: 예산한도/1인당 | F3: 집행액(합계) | G3: 미집행(초과집행) | K3: 예산한도/1인당 | L3: 집행액(합계) | M3: 미집행(초과집행)
F4: =SUM(F5:F49971) -> 1550000 | L4: =SUM(L5:L49971) -> 0
B5: 1 | C5: 홍길동 | E5: 2400000 | F5: =SUMIF('직접비-역량강화지원금'!$G$8:$G$50000,C5,'직접비-역량강화지원금'!$J$8:$J$50000) -> 100000 | G5: =+E5-F5 -> 2300000 | I5: 기타 - 애로사항 | J5: =CONCATENATE(I5,C5) -> 기타 - 애로사항홍길동 | K5: 1200000 | L5: =SUMIF('직접비-역량강화지원금'!$B$8:$B$50000,참여청년현황!J5,'직접비-역량강화지원금'!$J$8:$J$50000) -> 0 | M5: =+K5-L5 -> 1200000
B6: 2 | C6: 홍길순 | E6: 2400000 | F6: =SUMIF('직접비-역량강화지원금'!$G$8:$G$50000,C6,'직접비-역량강화지원금'!$J$8:$J$50000) -> 1450000 | G6: =+E6-F6 -> 950000 | I6: 기타 - 애로사항 | J6: =CONCATENATE(I6,C6) -> 기타 - 애로사항홍길순 | K6: 1200000 | L6: =SUMIF('직접비-역량강화지원금'!$B$8:$B$50000,참여청년현황!J6,'직접비-역량강화지원금'!$J$8:$J$50000) -> 0 | M6: =+K6-L6 -> 1200000
B7: 3 | E7: 2400000 | F7: =SUMIF('직접비-역량강화지원금'!$G$8:$G$50000,C7,'직접비-역량강화지원금'!$J$8:$J$50000) -> 0 | G7: =+E7-F7 -> 2400000 | I7: 기타 - 애로사항 | J7: =CONCATENATE(I7,C7) -> 기타 - 애로사항 | K7: 1200000 | L7: =SUMIF('직접비-역량강화지원금'!$B$8:$B$50000,참여청년현황!J7,'직접비-역량강화지원금'!$J$8:$J$50000) -> 0 | M7: =+K7-L7 -> 1200000
B8: 4 | E8: 2400000 | F8: =SUMIF('직접비-역량강화지원금'!$G$8:$G$50000,C8,'직접비-역량강화지원금'!$J$8:$J$50000) -> 0 | G8: =+E8-F8 -> 2400000 | I8: 기타 - 애로사항 | J8: =CONCATENATE(I8,C8) -> 기타 - 애로사항 | K8: 1200000 | L8: =SUMIF('직접비-역량강화지원금'!$B$8:$B$50000,참여청년현황!J8,'직접비-역량강화지원금'!$J$8:$J$50000) -> 0 | M8: =+K8-L8 -> 1200000
B9: 5 | E9: 2400000 | F9: =SUMIF('직접비-역량강화지원금'!$G$8:$G$50000,C9,'직접비-역량강화지원금'!$J$8:$J$50000) -> 0 | G9: =+E9-F9 -> 2400000 | I9: 기타 - 애로사항 | J9: =CONCATENATE(I9,C9) -> 기타 - 애로사항 | K9: 1200000 | L9: =SUMIF('직접비-역량강화지원금'!$B$8:$B$50000,참여청년현황!J9,'직접비-역량강화지원금'!$J$8:$J$50000) -> 0 | M9: =+K9-L9 -> 1200000
B10: 6 | E10: 2400000 | F10: =SUMIF('직접비-역량강화지원금'!$G$8:$G$50000,C10,'직접비-역량강화지원금'!$J$8:$J$50000) -> 0 | G10: =+E10-F10 -> 2400000 | I10: 기타 - 애로사항 | J10: =CONCATENATE(I10,C10) -> 기타 - 애로사항 | K10: 1200000 | L10: =SUMIF('직접비-역량강화지원금'!$B$8:$B$50000,참여청년현황!J10,'직접비-역량강화지원금'!$J$8:$J$50000) -> 0 | M10: =+K10-L10 -> 1200000
B11: 7 | E11: 2400000 | F11: =SUMIF('직접비-역량강화지원금'!$G$8:$G$50000,C11,'직접비-역량강화지원금'!$J$8:$J$50000) -> 0 | G11: =+E11-F11 -> 2400000 | I11: 기타 - 애로사항 | J11: =CONCATENATE(I11,C11) -> 기타 - 애로사항 | K11: 1200000 | L11: =SUMIF('직접비-역량강화지원금'!$B$8:$B$50000,참여청년현황!J11,'직접비-역량강화지원금'!$J$8:$J$50000) -> 0 | M11: =+K11-L11 -> 1200000
B12: 8 | E12: 2400000 | F12: =SUMIF('직접비-역량강화지원금'!$G$8:$G$50000,C12,'직접비-역량강화지원금'!$J$8:$J$50000) -> 0 | G12: =+E12-F12 -> 2400000 | I12: 기타 - 애로사항 | J12: =CONCATENATE(I12,C12) -> 기타 - 애로사항 | K12: 1200000 | L12: =SUMIF('직접비-역량강화지원금'!$B$8:$B$50000,참여청년현황!J12,'직접비-역량강화지원금'!$J$8:$J$50000) -> 0 | M12: =+K12-L12 -> 1200000
B13: 9 | E13: 2400000 | F13: =SUMIF('직접비-역량강화지원금'!$G$8:$G$50000,C13,'직접비-역량강화지원금'!$J$8:$J$50000) -> 0 | G13: =+E13-F13 -> 2400000 | I13: 기타 - 애로사항 | J13: =CONCATENATE(I13,C13) -> 기타 - 애로사항 | K13: 1200000 | L13: =SUMIF('직접비-역량강화지원금'!$B$8:$B$50000,참여청년현황!J13,'직접비-역량강화지원금'!$J$8:$J$50000) -> 0 | M13: =+K13-L13 -> 1200000
B14: 10 | E14: 2400000 | F14: =SUMIF('직접비-역량강화지원금'!$G$8:$G$50000,C14,'직접비-역량강화지원금'!$J$8:$J$50000) -> 0 | G14: =+E14-F14 -> 2400000 | I14: 기타 - 애로사항 | J14: =CONCATENATE(I14,C14) -> 기타 - 애로사항 | K14: 1200000 | L14: =SUMIF('직접비-역량강화지원금'!$B$8:$B$50000,참여청년현황!J14,'직접비-역량강화지원금'!$J$8:$J$50000) -> 0 | M14: =+K14-L14 -> 1200000
B15: 11 | E15: 2400000 | F15: =SUMIF('직접비-역량강화지원금'!$G$8:$G$50000,C15,'직접비-역량강화지원금'!$J$8:$J$50000) -> 0 | G15: =+E15-F15 -> 2400000 | I15: 기타 - 애로사항 | J15: =CONCATENATE(I15,C15) -> 기타 - 애로사항 | K15: 1200000 | L15: =SUMIF('직접비-역량강화지원금'!$B$8:$B$50000,참여청년현황!J15,'직접비-역량강화지원금'!$J$8:$J$50000) -> 0 | M15: =+K15-L15 -> 1200000
B16: 12 | E16: 2400000 | F16: =SUMIF('직접비-역량강화지원금'!$G$8:$G$50000,C16,'직접비-역량강화지원금'!$J$8:$J$50000) -> 0 | G16: =+E16-F16 -> 2400000 | I16: 기타 - 애로사항 | J16: =CONCATENATE(I16,C16) -> 기타 - 애로사항 | K16: 1200000 | L16: =SUMIF('직접비-역량강화지원금'!$B$8:$B$50000,참여청년현황!J16,'직접비-역량강화지원금'!$J$8:$J$50000) -> 0 | M16: =+K16-L16 -> 1200000
B17: 13 | E17: 2400000 | F17: =SUMIF('직접비-역량강화지원금'!$G$8:$G$50000,C17,'직접비-역량강화지원금'!$J$8:$J$50000) -> 0 | G17: =+E17-F17 -> 2400000 | I17: 기타 - 애로사항 | J17: =CONCATENATE(I17,C17) -> 기타 - 애로사항 | K17: 1200000 | L17: =SUMIF('직접비-역량강화지원금'!$B$8:$B$50000,참여청년현황!J17,'직접비-역량강화지원금'!$J$8:$J$50000) -> 0 | M17: =+K17-L17 -> 1200000
B18: 14 | E18: 2400000 | F18: =SUMIF('직접비-역량강화지원금'!$G$8:$G$50000,C18,'직접비-역량강화지원금'!$J$8:$J$50000) -> 0 | G18: =+E18-F18 -> 2400000 | I18: 기타 - 애로사항 | J18: =CONCATENATE(I18,C18) -> 기타 - 애로사항 | K18: 1200000 | L18: =SUMIF('직접비-역량강화지원금'!$B$8:$B$50000,참여청년현황!J18,'직접비-역량강화지원금'!$J$8:$J$50000) -> 0 | M18: =+K18-L18 -> 1200000
... B24: 20 | E24: 2400000 | F24: =SUMIF('직접비-역량강화지원금'!$G$8:$G$50000,C24,'직접비-역량강화지원금'!$J$8:$J$50000) -> 0 | G24: =+E24-F24 -> 2400000 | I24: 기타 - 애로사항 | J24: =CONCATENATE(I24,C24) -> 기타 - 애로사항 | K24: 1200000 | L24: =SUMIF('직접비-역량강화지원금'!$B$8:$B$50000,참여청년현황!J24,'직접비-역량강화지원금'!$J$8:$J$50000) -> 0 | M24: =+K24-L24 -> 1200000
A25: ※ 지역제작소별 참여청년 20명
A26: ※ 애로사항 해소지원 포함하여 전체 금액 240만원(총예산 및 집행)

Sheet 간접비-보수
B2: 간접사업비- 보수(인건비)
B4: 전담인원 | C4: 입사일자 | D4: 퇴사일자 | E4: 참여시작일 | F4: 참여종료일 | I4: 집행예산액 | J4: =+'사업비 사용실적 명세서'!G33 -> 45000000
B5: 홍길동 | C5: 45292 | D5: 45596 | E5: 45352 | F5: 45596 | I5: 집행금액 | J5: =+'사업비 사용실적 명세서'!I15 -> 43050000 | K5: =+I13-J5 -> 0
I6: 미집행(초과집행) | J6: =+J4-J5 -> 1950000
B12: 증빙 번호 | C12: 집행일 | D12: 대상인원 | E12: 적요 | H12: 집행방법 (카드, 계좌이체 등) | I12: 지출금액 (합계) | J12: 비고
I13: =SUM(I14:I49999) -> 43050000
B14: 1 | C14: 45383 | D14: 홍길동 | E14: 1월 급여 | H14: 계좌이체 | I14: 43000000
B15: 2 | C15: 45413 | H15: 계좌이체 | I15: 50000
B16: 3
B17: 4
B18: 5
B19: 6
B20: 7
B21: 8
B22: 9
B23: 10
B24: 11
B25: 12
B26: 13
B27: 14
... B45: 32

Sheet 간접비-일반운영비
I2: 구분 | J2: 지출금액
I3: 일반수용비(홍보비 외) | J3: =SUMIF($D$21:$D$50000,I3,$J$21:$J$50000) -> 351456
I4: 일반수용비(홍보비) | J4: =SUMIF($D$21:$D$50000,I4,$J$21:$J$50000) -> 50000
I5: 공공요금 및 제세 | J5: =SUMIF($D$21:$D$50000,I5,$J$21:$J$50000) -> 0
I6: 특근매식비 | J6: =SUMIF($D$21:$D$50000,I6,$J$21:$J$50000) -> 0
I7: [합 계] | J7: =SUM(J3:J6) -> 401456
J8: =+J7-J20 -> 0
N12: 홍보비 예산 한도 검토
B13: 간접비-일반운영비 | F13: 구분 | G13: 일반수용비(홍보비 외) | H13: 일반수용비(홍보비) | I13: 공공요금 및 제세 | J13: 특근매식비 | K13: [합 계] | N13: 간접비 예산 | P13: =+'사업비 사용실적 명세서'!G24 -> 53300000
F14: 집행예산액 | G14: =+'사업비 사용실적 명세서'!G34 -> 900000 | H14: =+'사업비 사용실적 명세서'!G35 -> 800000 | I14: =+'사업비 사용실적 명세서'!G36 -> 700000 | J14: =+'사업비 사용실적 명세서'!G37 -> 600000 | K14: =+G14+H14+I14+J14 -> 3000000 | N14: 홍보비 예산 | P14: =+H14 -> 800000
F15: 집행금액 | G15: =+'사업비 사용실적 명세서'!I34 -> 351456 | H15: =+'사업비 사용실적 명세서'!I35 -> 50000 | I15: =+'사업비 사용실적 명세서'!I36 -> 0 | J15: =+'사업비 사용실적 명세서'!I37 -> 0 | K15: =+G15+H15+I15+J15 -> 401456 | L15: =+J20-K15 -> 0 | N15: 비율(10% 이내) | P15: =+P14/P13 -> 0.015009381
F16: 미집행(초과집행) | G16: =+G14-G15 -> 548544 | H16: =+H14-H15 -> 750000 | I16: =+I14-I15 -> 700000 | J16: =+J14-J15 -> 600000 | K16: =+K14-K15 -> 2598544 | P16: =IF(P15>10%,"초과설정","OK") -> OK
B19: 증빙 번호 | C19: 집행일 | D19: 세세목 | E19: 거래처명 | F19: 적요 | I19: 집행방법 (카드, 계좌이체 등) | J19: 지출금액 (합계) | K19: 비고
J20: =SUM(J21:J50000) -> 401456
B21: 1 | C21: 45383 | D21: 일반수용비(홍보비 외) | E21: 호시담 | F21: 참여청년 심리상담 비용 2건 지급(윤원일) | I21: 계좌이체 | J21: 321456
B22: 2 | C22: 45413 | D22: 일반수용비(홍보비) | E22: 상공회의소 | F22: 자격증 응시료 자기부담금(우미리) | I22: 계좌이체 | J22: 50000
B23: 3 | D23: 일반수용비(홍보비 외) | J23: 30000
B24: 4 | D24: 특근매식비
B25: 5
B26: 6
B27: 7
B28: 8
B29: 9
B30: 10
B31: 11
B32: 12
B33: 13
B34: 14
B35: 15
B36: 16
... B162: 142

Sheet 간접비-여비
B2: 간접비-여비 | H2: 집행예산액 | I2: =+'사업비 사용실적 명세서'!G38 -> 400000
H3: 집행금액 | I3: =+'사업비 사용실적 명세서'!I38 -> 61110 | J3: =+H7-I3 -> 0
H4: 미집행(초과집행) | I4: =+I2-I3 -> 338890
B6: 증빙 번호 | C6: 집행일 | D6: 대상인원 | E6: 목적지 | F6: 적요 | G6: 집행방법 (카드, 계좌이체 등) | H6: 지출금액 (합계) | I6: 비고
H7: =SUM(H8:H49999) -> 61110
B8: 1 | C8: 45383 | D8: 호시담 | E8: 서울 | F8: 참여청년 심리상담 비용 2건 지급(윤원일) | G8: 계좌이체 | H8: 11110
B9: 2 | C9: 45413 | D9: 상공회의소 | E9: 부산 | F9: 자격증 응시료 자기부담금(우미리) | G9: 계좌이체 | H9: 50000
B10: 3
B11: 4
B12: 5
B13: 6
B14: 7
B15: 8
B16: 9
B17: 10
B18: 11
B19: 12
B20: 13
B21: 14
... B47: 40

Sheet 간접비-업무추진비
M2: 사업추진비 예산 한도 검토
B3: 간접비-업무추진비 | I3: 집행예산액 | J3: =+'사업비 사용실적 명세서'!G39 -> 300000 | M3: 운영인건비 예산 | O3: =+'사업비 사용실적 명세서'!G15+'사업비 사용실적 명세서'!G20 -> 49500000
I4: 집행금액 | J4: =+'사업비 사용실적 명세서'!I39 -> 280000 | K4: =+I9-J4 -> 0 | M4: 사업추진비 예산 | O4: =+J3 -> 300000
I5: 미집행(초과집행) | J5: =+J3-J4 -> 20000 | M5: 비율(5%이내) | O5: =+O4/O3 -> 0.0060606061
O6: =IF(O5>5%,"초과설정","OK") -> OK
B8: 증빙 번호 | C8: 집행일 | D8: 세세목 | E8: 참석인원수(명) | F8: 업체명/성명 | G8: 적요 | H8: 집행방법 (카드, 계좌이체 등) | I8: 지출금액 (합계) | J8: 비고
I9: =SUM(I10:I49999) -> 280000
B10: 1 | C10: 45383 | D10: 회의비 | E10: 3 | F10: 스타벅스 | G10: ㅇㅇㅇ 회의 | H10: 카드 | I10: 90000 | J10: =IFERROR(IF((I10)/E10>30000,"한도초과","OK"),"-") -> OK
B11: 2 | C11: 45413 | D11: 사업추진비 | E11: 5 | F11: 백다방 | G11: ㅇㅇㅇ 회의 | H11: 카드 | I11: 160000 | J11: =IFERROR(IF((I11)/E11>30000,"한도초과","OK"),"-") -> 한도초과
B12: 3 | E12: 1 | I12: 30000 | J12: =IFERROR(IF((I12)/E12>30000,"한도초과","OK"),"-") -> OK
B13: 4 | J13: =IFERROR(IF((I13)/E13>30000,"한도초과","OK"),"-") -> -
B14: 5 | J14: =IFERROR(IF((I14)/E14>30000,"한도초과","OK"),"-") -> -
B15: 6 | J15: =IFERROR(IF((I15)/E15>30000,"한도초과","OK"),"-") -> -
B16: 7 | J16: =IFERROR(IF((I16)/E16>30000,"한도초과","OK"),"-") -> -
B17: 8 | J17: =IFERROR(IF((I17)/E17>30000,"한도초과","OK"),"-") -> -
B18: 9 | J18: =IFERROR(IF((I18)/E18>30000,"한도초과","OK"),"-") -> -
B19: 10 | J19: =IFERROR(IF((I19)/E19>30000,"한도초과","OK"),"-") -> -
B20: 11 | J20: =IFERROR(IF((I20)/E20>30000,"한도초과","OK"),"-") -> -
B21: 12 | J21: =IFERROR(IF((I21)/E21>30000,"한도초과","OK"),"-") -> -
B22: 13 | J22: =IFERROR(IF((I22)/E22>30000,"한도초과","OK"),"-") -> -
B23: 14 | J23: =IFERROR(IF((I23)/E23>30000,"한도초과","OK"),"-") -> -
B24: 15 | J24: =IFERROR(IF((I24)/E24>30000,"한도초과","OK"),"-") -> -
... B48: 39 | J48: =IFERROR(IF((I48)/E48>30000,"한도초과","OK"),"-") -> -

Sheet 간접비-기타직보수
B2: 간접사업비- 기타직보수 | I2: 집행예산액 | J2: =+'사업비 사용실적 명세서'!G41 -> 4500000
I3: 집행금액 | J3: =+'사업비 사용실적 명세서'!I41 -> 550000 | K3: =+I7-J3 -> 0
I4: 미집행(초과집행) | J4: =+J2-J3 -> 3950000
B6: 증빙 번호 | C6: 집행일 | D6: 대상인원 | E6: 적요 | H6: 집행방법 (카드, 계좌이체 등) | I6: 지출금액 (합계) | J6: 비고
I7: =SUM(I8:I49999) -> 550000
B8: 1 | C8: 45383 | D8: 홍길동 | E8: 1월 급여 | H8: 계좌이체 | I8: 500000
B9: 2 | C9: 45413 | H9: 계좌이체 | I9: 50000
B10: 3
B11: 4
B12: 5
B13: 6
B14: 7
B15: 8
B16: 9
B17: 10
B18: 11
B19: 12
B20: 13
B21: 14
... B39: 32

Sheet 참고)비목별 세부집행기준
A1: □ 공통 기본 서류
A2: ○ 지출결의서(품의서), 역량강화지원금 신청서(청년용, 서식10)
A3: ○ 사용내역 1) (세금계산서) 거래처 사업자등록증 및 통장사본, 세금계산서 2) (카드결제) 구매사이트 화면캡쳐본, 거래명세서, 카드전표(영수증) 3) (청년 개인 계좌이체) 신분증 및 통장사본, 이체내역서
A4: ※계약은 계약서, 거래명세서 또는 견적서 필요
A6: □ 직접사업비(역량강화지원금)
A7: ※ 개인별프로그램 계획서를 참조하여 지급
A9: 운영주체 | B9: 구분/내용 | D9: 세부내용 | E9: 필요증빙서류 | F9: 실비지급(청년 직접지급)
A10: 제작소 | B10: [1]제작소 자체 특화프로그램 | D10: 공동운영프로그램, 멘토링, 강의(특강) 등 | E10: 1. 프로그램 운영 계획서 (커리큘럼 등 포함) 2. 전문가 이력서 3. 위탁계약서4. 결과보고서 및 출결증빙 | F10: 불가
D11: 프로그램 운영 부대비용
A12: 제작소/외부기관 | B12: 생활기술 | C12: 라이프코칭 | D12: 멘토링 및 강의(특강)지원, 커뮤니티지원, | E12: 〔강의(특강) 및 컨설팅 지원〕프로그램 커리큘럼, 전문가 이력서, 위탁계약서, 계좌이체증명, 프로그램 운영 및 결과자료, 출결확인증 〔커뮤니티지원〕커뮤니티 운영계획서 및 보고서, 참석확인증
A13: 외부기관 | C13: 금융/법률 기초상식 | D13: 컨설팅 및 강의(특강)지원
A14: 제작소 | C14: 지지기반 | D14: 소규모 멘토링, 커뮤니티지원
A15: 제작소 | B15: 자기발견 | C15: 진로설계 | D15: 심리검사(MBTI, 다중지능검사, DISC 등), 진로상담 | E15: 1. 검사 비용 및 검사지 구매권
A16: 외부기관 | C16: 마음건강 | D16: 심리상담 외부위탁비 | E16: 1. 심리상담 전문가 이력서 2. 외부위탁용역 계약서(협약서) 3. 운영내역·결과자료 4. 상담사실 확인서
A17: 정부·지자체/외부기관 | B17: 자립지원 | C17: [2] 자립 훈련·수강 자기부담금 | D17: 학원, 인터넷강의, 멘토링 | E17: 1. 훈련·수강 커리큘럼 2. 기관 정보 3. 수강 확인증 4. 수료증 * [중도 포기·탈락 시]사유서 | F17: 가능
D18: 불가피한 교재(재료)
D19: (창업)시제품 개발·재료 | E19: 1. 재단 협의공문 2. 비용 예산 반영 계획서 3. 견적서
D20: 자격증 응시료 | E20: 1. 자격시험 접수증 2. 응시확인서, (응시결과서류) * [미 응시 시] 지급불가
D21: 불가피한 교재(재료)
D22: 면접 사진, 정장대여 | E22: 기관정보, 촬영 및 대여자료
C23: [3]교육·면접 참가수당 | D23: 거주 지역 외 타 지역으로 이동한 경우 (단, 시외버스, 기차, 항공, 선박에 한함) | E23: 1. 교육·훈련·면접 참여 확인서 2. 청년 인적사항(거주지 표시) 3. 교통비 영수증 * [일자 불일치 시] 지급불가
C24: [4]인턴쉽 | D24: 프로그램 인건비 | E24: 1. 재단 협의공문 2. 협약서 또는 근로계약서 3. 출근부, 급여명세서 등 | F24: 불가 *단, 기관사정상 협의가능
A26: ※ 사업비 사용 제한업종은 청년다다름사업 사업비 예산편성 및 집행지침「붙임7 사업비 사용 제한업종」, 강사료 및 원고료는 청년다다름사업 사업비 예산편성 및 집행지침「붙임5 외부강사료 및 원고료 지급기준」에 따름
A28: ○ [1]참여청년 맞춤형으로 설계된 제작소 자체 프로그램 운영 시 사용
A29: - 참여청년들 공동 운영 프로그램의 경우, 해당청년 ‘역량강화지원비’비목에서 나누어(1/n) 집행하고, 출결확인자료 증빙
A30: * 제작소특화프로그램 진행에 소요되는 인쇄물, 다과, 렌탈비 등의 부대비용 포함(간접사업비 집행기준과 동일)
A32: ○ 심리상담을 외부 위탁을 통해서 유료로 진행할 경우 사용, 내부 인프라 활용 시 비용지급 불가
A34: ○ 심리검사는 무료를 우선으로 진행하되, 필요시 검사지를 구매하여 진행
A36: ○ [2]정부 및 지자체를 포함한 외부기관에서 개설한 훈련 수강을 위한 비용, 미지원 항목(자기부담금), 자격증 취득비
A37: - 훈련·수강·자격증 취득의 취소·중도 탈락(포기)의 경우 증빙서류에 사유서 첨부 필요
A38: * 대상 청년에게 각종 수당, 장학금 등을 직접 지급하는 것은 원칙적으로 불가하나, 아래 항목에 한하여 청년에게 실비지급 가능
A39: ① ‘국민내일배움카드(구,내일배움카드)’ 훈련수강으로 인해 발생하는 자비부담금에 한하여, 해당 청년 명의의 계좌로 지급 가능 (훈련내용,기관정보,카드계좌정보 등 증빙)
A40: ② 자격증 취득 비용 지급의 경우, 자격증 시험 신청영수증, 응시확인서, 수험표가 증빙된 건에 한하여 인정되며, 증빙서류 확인 후 청년 실비 지급 가능(응시확인서가 없는 경우 응시결과서류 확인이 필요하며, 미 응시의 경우 시험비용을 반환하고 미 응시 사유서 필요)
A42: ○ [2]정부 및 지자체를 포함한 외부기관의 창업지원사업 미지원 항목(자기부담금), 시제품 개발비, 재료비
... A129: - 사업비를 과다하게 지출하지 않도록 하여야 하며, 수의계약을 지양하고 투명하게 거래처를 선정하여 집행

Sheet 증빙폴더 작성 방법
C29: pdf 파일 작성시 순서 예시
C30: 1. 지출결의서(품의서)
C31: 2. 역량강화지원금 신청서
C32: 3. 거래처 사업자등록증 및 통장사본
C33: 4. 세금계산서 or 카드전표 or 청년 개인계좌이체내역(신분증, 통장사본, 이체내역서)
C34: 5. 계약서, 거래명세서, 견적서
C35: 6. 결과보고서
C36: 7. 기타 집행 증빙
